[2023-04-03T19:20:18.270+0000] {processor.py:153} INFO - Started process (PID=16212) to work on /opt/airflow/dags/AIRFLOW_metadata_AZTzdaTZ_new01.py
[2023-04-03T19:20:18.271+0000] {processor.py:743} INFO - Processing file /opt/airflow/dags/AIRFLOW_metadata_AZTzdaTZ_new01.py for tasks to queue
[2023-04-03T19:20:18.272+0000] {logging_mixin.py:137} INFO - [2023-04-03T19:20:18.272+0000] {dagbag.py:538} INFO - Filling up the DagBag from /opt/airflow/dags/AIRFLOW_metadata_AZTzdaTZ_new01.py
[2023-04-03T19:20:18.272+0000] {processor.py:755} WARNING - No viable dags retrieved from /opt/airflow/dags/AIRFLOW_metadata_AZTzdaTZ_new01.py
[2023-04-03T19:20:18.345+0000] {logging_mixin.py:137} INFO - [2023-04-03T19:20:18.345+0000] {taskinstance.py:1774} ERROR - Executor reports task instance <TaskInstance: AIRFLOW_metadata_AZTzdaTZ_new01.ingestion_task manual__2023-04-03T19:20:02+00:00 [queued]> finished (failed) although the task says its queued. (Info: None) Was the task killed externally?
[2023-04-03T19:20:18.366+0000] {logging_mixin.py:137} INFO - [2023-04-03T19:20:18.365+0000] {taskinstance.py:1322} INFO - Marking task as FAILED. dag_id=AIRFLOW_metadata_AZTzdaTZ_new01, task_id=ingestion_task, execution_date=20230403T192002, start_date=, end_date=20230403T192018
[2023-04-03T19:20:18.367+0000] {logging_mixin.py:137} INFO - [2023-04-03T19:20:18.366+0000] {taskinstance.py:1540} ERROR - Error when executing on_failure callback
Traceback (most recent call last):
  File "/home/airflow/.local/lib/python3.8/site-packages/airflow/models/taskinstance.py", line 1538, in _run_finished_callback
    callback(context)
TypeError: 'str' object is not callable
[2023-04-03T19:20:18.379+0000] {processor.py:713} INFO - Executed failure callback for <TaskInstance: AIRFLOW_metadata_AZTzdaTZ_new01.ingestion_task manual__2023-04-03T19:20:02+00:00 [failed]> in state failed
[2023-04-03T19:20:18.383+0000] {processor.py:175} INFO - Processing /opt/airflow/dags/AIRFLOW_metadata_AZTzdaTZ_new01.py took 0.115 seconds
